Workbook

Sheet 물성전체
A1: C/SiC 평직 복합재 UMAT 물성 대장
A2: 재현 대상: Zhang et al. 2022, Ceram. Int. 48:3109-3124
A3: 상태 구분 | 검증완료: 논문 직접 인용 또는 유도 후 수치 재검증 완료 | 보정값: 논문에 없어 Table 3 에 맞춰 역보정 | 임시값: 논문에 없고 미보정 | 수치설정: 물성이 아닌 수치해석 파라미터 | 미검증: 논문과 다르며 영향 미확인
A5: 구분 | B5: 물성 이름 | C5: 기능 | D5: 값 | E5: 단위 | F5: 출처 | G5: 상태 | H5: 비고
A6: A. T300 섬유 (논문 Table 1)
A7: A | B7: Ef1 | C7: 섬유 축(1)방향 탄성계수 | D7: 230 | E7: GPa | F7: Zhang et al. 2022, Ceram. Int. 48:3109-3124 Table 1 [34,35] | G7: 검증완료 | H7: 논문 직접 인용
A8: A | B8: Ef2 | C8: 섬유 횡(2,3)방향 탄성계수 | D8: 40 | E8: GPa | F8: Zhang et al. 2022, Ceram. Int. 48:3109-3124 Table 1 | G8: 검증완료 | H8: 논문 직접 인용
A9: A | B9: Gf12 | C9: 섬유 면내 전단탄성계수 | D9: 24 | E9: GPa | F9: Zhang et al. 2022, Ceram. Int. 48:3109-3124 Table 1 | G9: 검증완료 | H9: 논문 직접 인용
A10: A | B10: Gf23 | C10: 섬유 횡방향 전단탄성계수 | D10: 14.3 | E10: GPa | F10: Zhang et al. 2022, Ceram. Int. 48:3109-3124 Table 1 | G10: 검증완료 | H10: 논문 직접 인용
A11: A | B11: nu_f12 | C11: 섬유 주 포아송비 | D11: 0.26 | E11: - | F11: Zhang et al. 2022, Ceram. Int. 48:3109-3124 Table 1 | G11: 검증완료 | H11: 논문 직접 인용
A12: A | B12: Xf,t | C12: 섬유 축방향 인장강도 | D12: 3580 | E12: MPa | F12: Zhang et al. 2022, Ceram. Int. 48:3109-3124 Table 1 | G12: 검증완료 | H12: 얀 강도 환산의 상한 기준
A13: A | B13: Xf,c | C13: 섬유 축방향 압축강도 | D13: 2470 | E13: MPa | F13: Zhang et al. 2022, Ceram. Int. 48:3109-3124 Table 1 | G13: 검증완료 | H13: 논문 직접 인용
A14: A | B14: alpha_f1 | C14: 섬유 축방향 열팽창계수 | D14: -3e-07 | E14: 1/K | F14: Zhang et al. 2022, Ceram. Int. 48:3109-3124 Table 1 | G14: 검증완료 | H14: 음수. 기지와의 불일치가 잔류응력 원인
A15: A | B15: alpha_f2(3) | C15: 섬유 횡방향 열팽창계수 | D15: 3.1e-06 | E15: 1/K | F15: Zhang et al. 2022, Ceram. Int. 48:3109-3124 Table 1 | G15: 검증완료 | H15: 논문 직접 인용
A16: B. SiC 기지 (논문 Table 2)
A17: B | B17: Em | C17: 기지 탄성계수 | D17: 350 | E17: GPa | F17: Zhang et al. 2022, Ceram. Int. 48:3109-3124 Table 2 [35-37] | G17: 검증완료 | H17: 논문 직접 인용
A18: B | B18: Gm | C18: 기지 전단탄성계수 | D18: 146 | E18: GPa | F18: Zhang et al. 2022, Ceram. Int. 48:3109-3124 Table 2 | G18: 검증완료 | H18: E/(2(1+nu))=145.83 과 0.11% 일치 (자기무모순 확인)
A19: B | B19: nu_m | C19: 기지 포아송비 | D19: 0.2 | E19: - | F19: Zhang et al. 2022, Ceram. Int. 48:3109-3124 Table 2 | G19: 검증완료 | H19: 논문 직접 인용
A20: B | B20: Xm,t(c) | C20: 기지 인장=압축 강도 | D20: 310 | E20: MPa | F20: Zhang et al. 2022, Ceram. Int. 48:3109-3124 Table 2 | G20: 검증완료 | H20: 논문이 인장·압축에 같은 값 하나만 제시
A21: B | B21: alpha_m | C21: 기지 열팽창계수 | D21: 4.5e-06 | E21: 1/K | F21: Zhang et al. 2022, Ceram. Int. 48:3109-3124 Table 2 | G21: 검증완료 | H21: 온도무관 상수 (논문 3.2.3)
A22: C. RVE 형상 · 체적분율
A23: C | B23: Lx | C23: RVE x 방향 치수 | D23: 3.5 | E23: mm | F23: Zhang et al. 2022, Ceram. Int. 48:3109-3124 3.2.1 | G23: 검증완료 | H23: 논문과 동일
A24: C | B24: Ly | C24: RVE y 방향 치수 | D24: 3.5 | E24: mm | F24: Zhang et al. 2022, Ceram. Int. 48:3109-3124 3.2.1 | G24: 검증완료 | H24: 논문과 동일
A25: C | B25: Lz | C25: RVE 두께 | D25: 0.44 | E25: mm | F25: 자체 TexGen 모델 | G25: 미검증 | H25: 논문은 0.4334 mm. 1.5% 차이 (영향 경미로 판단)
A26: C | B26: 타원 장축 | C26: 얀 단면 타원 장축 | D26: 1.28 | E26: mm | F26: Zhang et al. 2022, Ceram. Int. 48:3109-3124 3.2.1 | G26: 검증완료 | H26: 논문과 동일
A27: C | B27: 타원 단축 | C27: 얀 단면 타원 단축 | D27: 0.2 | E27: mm | F27: Zhang et al. 2022, Ceram. Int. 48:3109-3124 3.2.1 | G27: 검증완료 | H27: 논문과 동일
A28: C | B28: V_RVE | C28: RVE 총 체적 | D28: 5.39 | E28: mm^3 | F28: 메쉬 적분 (자체 검증) | G28: 검증완료 | H28: 3.5 x 3.5 x 0.44 와 정확히 일치
A29: C | B29: Vf_tow | C29: 얀 내부 섬유체적분율 | D29: 0.79194 | E29: - | F29: 얀 물성 역산 (논문 미기재) | G29: 검증완료 | H29: 이 값에서 전체 Vf=0.400 이 재현됨
A30: C | B30: V_tow/V_RVE | C30: 얀(tow) 체적분율 | D30: 0.5051 | E30: - | F30: 메쉬 적분 | G30: 검증완료 | H30: 자체 계산
A31: C | B31: Vf_total | C31: 전체 섬유체적분율 | D31: 0.4 | E31: - | F31: 0.79194 x 0.5051 | G31: 검증완료 | H31: 논문 명시값 40% 와 정확히 일치
A32: C | B32: N_elem | C32: C3D4 요소 개수 | D32: 174405 | E32: 개 | F32: 자체 TexGen 메쉬 | G32: 미검증 | H32: 논문은 116,724개. 1.5배 조밀 (메쉬수렴성 미검증)
A33: D. 얀 균질화 물성 (Chamis / Schapery)
A34: D | B34: Ey1 | C34: 얀 축방향 탄성계수 | D34: 254967.23 | E34: MPa | F34: Chamis 혼합법칙 [32] | G34: 검증완료 | H34: 재계산 오차 -0.000011%
A35: D | B35: Ey2 | C35: 얀 횡방향 탄성계수 | D35: 44321.738 | E35: MPa | F35: Chamis [32] | G35: 검증완료 | H35: 재계산 오차 -0.000013%
A36: D | B36: Ey3 | C36: 얀 횡방향 탄성계수 | D36: 44321.738 | E36: MPa | F36: =Ey2 (횡등방) | G36: 검증완료 | H36: 횡등방성 가정
A37: D | B37: nu_y12 | C37: 얀 주 포아송비 | D37: 0.24751639 | E37: - | F37: Chamis 혼합법칙 | G37: 검증완료 | H37: 재계산 오차 +0.000006%
A38: D | B38: nu_y13 | C38: 얀 주 포아송비 | D38: 0.24751639 | E38: - | F38: =nu_y12 | G38: 검증완료 | H38: 횡등방성 가정
A39: D | B39: nu_y23 | C39: 얀 횡방향 포아송비 | D39: 0.39581358 | E39: - | F39: Ey2/(2Gy23)-1 | G39: 검증완료 | H39: 재계산 오차 +0.0048%
A40: D | B40: Gy12 | C40: 얀 면내 전단탄성계수 | D40: 26431.515 | E40: MPa | F40: Chamis [32] | G40: 검증완료 | H40: 재계산 오차 -0.0023%
A41: D | B41: Gy13 | C41: 얀 면내 전단탄성계수 | D41: 26431.515 | E41: MPa | F41: =Gy12 | G41: 검증완료 | H41: 횡등방성 가정
...

Sheet 균질화검증
A1: 얀 물성 균질화 재검증 (Chamis 강성 / Schapery·Chamis 열팽창)
A2: 아래 파란 셀이 입력이다. Vf_tow 를 바꾸면 계산열이 전부 갱신된다.
A4: 입력값 | F4: 계산 결과 vs UMAT 카드 값
A5: 기호 | B5: 값 | C5: 단위 | D5: 출처 | F5: 물성 | G5: 식으로 계산 | H5: UMAT 카드값 | I5: 오차 %
A6: Ef1 | B6: 230000 | C6: MPa | D6: 논문 Table 1 | F6: Ey1 | G6: =B16*B6+(1-B16)*B13 | H6: 254967.23 | I6: =IFERROR((G6/H6-1)*100,"")
A7: Ef2 | B7: 40000 | C7: MPa | D7: 논문 Table 1 | F7: Ey2 | G7: =B13/(1-SQRT(B16)*(1-B13/B7)) | H7: 44321.738 | I7: =IFERROR((G7/H7-1)*100,"")
A8: Gf12 | B8: 24000 | C8: MPa | D8: 논문 Table 1 | F8: Gy12 | G8: =(B13/(2*(1+B14)))/(1-SQRT(B16)*(1-(B13/(2*(1+B14)))/B8)) | H8: 26431.515 | I8: =IFERROR((G8/H8-1)*100,"")
A9: Gf23 | B9: 14300 | C9: MPa | D9: 논문 Table 1 | F9: Gy23 | G9: =(B13/(2*(1+B14)))/(1-SQRT(B16)*(1-(B13/(2*(1+B14)))/B9)) | H9: 15876.668 | I9: =IFERROR((G9/H9-1)*100,"")
A10: nu_f12 | B10: 0.26 | C10: - | D10: 논문 Table 1 | F10: nu_y12 | G10: =B16*B10+(1-B16)*B14 | H10: 0.24751639 | I10: =IFERROR((G10/H10-1)*100,"")
A11: alpha_f1 | B11: -3e-07 | C11: 1/K | D11: 논문 Table 1 | F11: nu_y23 | G11: =G7/(2*G9)-1 | H11: 0.39581358 | I11: =IFERROR((G11/H11-1)*100,"")
A12: alpha_f2 | B12: 3.1e-06 | C12: 1/K | D12: 논문 Table 1 | F12: alpha_y1 | G12: =(B16*B6*B11+(1-B16)*B13*B15)/(B16*B6+(1-B16)*B13) | H12: 1.070926e-06 | I12: =IFERROR((G12/H12-1)*100,"")
A13: Em | B13: 350000 | C13: MPa | D13: 논문 Table 2 | F13: alpha_y2 | G13: =B12*SQRT(B16)+(1-SQRT(B16))*(1+B16*B14*B6/G6)*B15 | H13: 3.3249086e-06 | I13: =IFERROR((G13/H13-1)*100,"")
A14: nu_m | B14: 0.2 | C14: - | D14: 논문 Table 2
A15: alpha_m | B15: 4.5e-06 | C15: 1/K | D15: 논문 Table 2 | F15: 판정 | G15: =IF(SUMPRODUCT(MAX(ABS(I6:I13)))<0.01,"전 항목 오차 0.01% 미만 - 균질화 검증 통과","오차 초과 항목 있음 - 확인 필요")
A16: Vf_tow | B16: 0.79194 | C16: - | D16: 역산 (논문 미기재)
F17: 참고: Chamis 이론 얀 인장강도 | G17: =B16*3580 | H17: MPa | I17: =421/G17*100 | J17: <- 현재 보정값 421 MPa 이 Chamis 이론값에서 차지하는 비율

Sheet 검증요약
A1: 검증 상태 요약
A3: 상태 | B3: 개수 | C3: 의미
A4: 검증완료 | B4: =COUNTIF(물성전체!$G$6:$G$107,A4) | C4: 논문 직접 인용, 또는 유도 후 수치 재검증 완료. 그대로 사용 가능
A5: 보정값 | B5: =COUNTIF(물성전체!$G$6:$G$107,A5) | C5: 논문에 값이 없어 Table 3 결과에 맞춰 역보정. 재현이 아닌 보정임을 논문에 명시 필요
A6: 임시값 | B6: =COUNTIF(물성전체!$G$6:$G$107,A6) | C6: 논문에 값이 없고 아직 보정도 안 됨. 결과 민감도 확인 필요
A7: 수치설정 | B7: =COUNTIF(물성전체!$G$6:$G$107,A7) | C7: 물성이 아닌 수치해석 파라미터. 물리적 의미 없음
A8: 미검증 | B8: =COUNTIF(물성전체!$G$6:$G$107,A8) | C8: 논문과 다르게 설정했고 영향을 아직 확인 못 함
A9: 합계 | B9: =SUM(B4:B8)
A12: 우선 처리 대상
A13: 항목 | B13: 내용
A14: 얀 PROPS 18 A1T | B14: 얀 축방향에 크랙밴드(Gf) 정규화가 없어 eta·메쉬 의존성의 근본 원인. eta 반감당 최대응력 4% 변동, 수렴점 없음. UMAT 수정 필요
A15: 얀 PROPS 11 XT | B15: 보정값 421 MPa 은 Chamis 이론값의 14.8%. 논문에 없는 값을 역보정한 것이므로 "재현"이 아니라 "보정"임을 반드시 명시
A16: 얀 PROPS 13 YT | B16: 횡방향 손상률(모델 88~93% vs 논문 99%)을 좌우하는데 미보정
A17: 기지 PROPS 8/9 DMAX | B17: 손상 상한 때문에 잔류강성이 남아 최대점 이후 응력이 비물리적으로 재상승
A18: C. 요소 개수 | B18: 174,405개 (논문 116,724개). 메쉬 수렴성 미검증. 단 얀 정규화가 없으면 수렴점 자체가 존재하지 않음
A19: C. RVE 두께 | B19: 0.44 mm (논문 0.4334 mm). 1.5% 차이, 영향 미확인
